Traceback (most recent call last):
  File "/home/WUR/zhou111/miniconda3/envs/myenv/lib/python3.10/site-packages/pandas/core/indexes/base.py", line 3805, in get_loc
    return self._engine.get_loc(casted_key)
  File "index.pyx", line 167, in pandas._libs.index.IndexEngine.get_loc
  File "index.pyx", line 196, in pandas._libs.index.IndexEngine.get_loc
  File "pandas/_libs/hashtable_class_helper.pxi", line 7081, in pandas._libs.hashtable.PyObjectHashTable.get_item
  File "pandas/_libs/hashtable_class_helper.pxi", line 7089, in pandas._libs.hashtable.PyObjectHashTable.get_item
KeyError: 'cPi'

The above exception was the direct cause of the following exception:

Traceback (most recent call last):
  File "/lustre/nobackup/WUR/ESG/zhou111/1_RQ1_Code/3_Results_Analysis/S2/P_Check.py", line 85, in <module>
    axes[2].plot(point_df["Date"], point_df["cPi"], label="cPi", color="tab:red")
  File "/home/WUR/zhou111/miniconda3/envs/myenv/lib/python3.10/site-packages/pandas/core/frame.py", line 4102, in __getitem__
    indexer = self.columns.get_loc(key)
  File "/home/WUR/zhou111/miniconda3/envs/myenv/lib/python3.10/site-packages/pandas/core/indexes/base.py", line 3812, in get_loc
    raise KeyError(key) from err
KeyError: 'cPi'
